<mujocoinclude>

  <body name='agv_link' pos='0.02371 0 0'>

    <site name="base_link" pos='-0.02371 0 0' size='0.001' type='sphere'/>

    <site name="laser" pos='0.09 0 0.215' size='0.001' type='sphere'/>


    <geom euler="0 0 0" type="box" rgba="1 0 0 1" group="0" size="0.21 0.2 0.005" pos="-0.015 0 0.235" density="725.0"/>
    <geom euler="0 0 0" type="box" rgba="1 0 0 1" group="0" size="0.21 0.2 0.08" pos="-0.015 0 0.11" density="725.0"/>
    <geom type="box" rgba="1 0 0 1" group="0" size="0.125 0.15 0.675" pos="-0.08 0 0.915" density="200.0"/>

    <geom name='rgt_front_wheel'  pos=" 0.13045 -0.089989 0.0585" mass='1.1566' type="sphere" size='0.06' rgba="1 0 0 1" group="0" condim='1' priority='1'/>
    <geom name='lft_front_wheel'  pos=" 0.13045  0.090011 0.0585" mass='1.1566' type="sphere" size='0.06' rgba="1 0 0 1" group="0" condim='1' priority='1'/>
    <geom name='rgt_behind_wheel' pos="-0.15755 -0.099989 0.0585" mass='1.1566' type="sphere" size='0.06' rgba="1 0 0 1" group="0" condim='1' priority='1'/>
    <geom name='lft_behind_wheel' pos="-0.15755  0.10001  0.0585" mass='1.1566' type="sphere" size='0.06' rgba="1 0 0 1" group="0" condim='1' priority='1'/>



    <body name="lft_wheel_link" pos="-0.02371 0.16325 0.082" euler="1.5707963267948966 0 0">
      <inertial pos="2.9309e-07 5.2077e-06 -0.029871" quat="0.28052 0.649078 -0.280681 0.649018" mass="1.1566" diaginertia="0.0035528 0.0021045 0.0021045"/>
      <joint name="lft_wheel_joint" class='wheel'/>
      <geom pos="0 0 0" type="cylinder" size='0.0838 0.005' rgba="0 1 0 1" group="0" friction="0.95"/>
    </body>

    <body name="rgt_wheel_link" pos="-0.02371 -0.16325 0.082" euler="1.5707963267948966 0 0">
      <inertial pos="2.9312e-07 5.2196e-06 0.029871" quat="0.620108 0.339813 -0.620017 0.339959" mass="1.1566" diaginertia="0.0035528 0.0021045 0.0021045"/>
      <joint name="rgt_wheel_joint" class='wheel'/>
      <geom pos="0 0 0" type="cylinder" size='0.0838 0.005' rgba="0 1 0 1" group="0" friction="0.95"/>
    </body>

    <body name="slide_link" pos="0 0 1.311">
      <joint name="slide_joint" class='slide_joint'/>
      <geom euler="0 0 0.7854" type="box" rgba="1 0 0 1" group="0" size="0.15 0.15 0.1" pos="0.035 0 0" density="80.0"/>
      <include file="head.xml"/>

      <body name="lft_arm_base" pos="0.034 0.1015 0" quat="0.65328 -0.65328 0.2706 -0.2706">
        <include file="arm_left.xml"/>
      </body>

      <body name="rgt_arm_base" pos="0.034 -0.1015 0" quat="0.65328 0.65328 0.2706 0.2706">
        <include file="arm_right.xml"/>
      </body>
    </body>

  </body>

</mujocoinclude>
